Workbook

Sheet Seguimiento
A1: Seguimiento de casos de prueba · Sistema de Gestión de Solicitudes de Usuario TI — MAF Chile · Fase 2
A2: Corte: 15-10-2026. Fuente: Plan y Casos de Prueba y Anexo de evidencia de ejecución.
A4: ID | B4: Módulo | C4: Caso de prueba | D4: Resultado esperado | E4: Crítico (automatizar) | F4: Fecha de ejecución | G4: Responsable | H4: Estado | I4: Resultado obtenido / observación | J4: Evidencia (Anexo) | K4: Defecto asociado
A5: CP-01 | B5: Ingreso | C5: Enviar formulario con campo obligatorio vacío | D5: Rechaza el envío y marca el campo faltante | E5: No | F5: 46305 | G5: Ariel Correa | H5: Pasa | I5: Pide completar todos los campos obligatorios antes de enviar. | J5: Fig. 1
A6: CP-02 | B6: Ingreso | C6: RUT con dígito verificador incorrecto | D6: Muestra “RUT inválido” | E6: Sí | F6: 46305 | G6: Ariel Correa | H6: Pasa | I6: Error al poner rut con dígito verificador incorrecto. | J6: Fig. 2
A7: CP-03 | B7: Ingreso | C7: RUT válido | D7: Acepta el dato | E7: No | F7: 46305 | G7: Ariel Correa | H7: Pasa | I7: Acepta RUT con dígito verificador válido. | J7: Fig. 3
A8: CP-04 | B8: Ingreso | C8: Fecha de nacimiento futura | D8: Muestra error de fecha inválida | E8: No | F8: 46305 | G8: Ariel Correa | H8: Pasa | I8: Error al poner fecha de nacimiento futura. | J8: Fig. 4
A9: CP-05 | B9: Ingreso | C9: Fecha que da menos de 18 o más de 75 años | D9: Muestra error de fecha inválida | E9: No | F9: 46305 | G9: Ariel Correa | H9: Pasa | I9: Error al poner fecha con edad menor a 18 años. | J9: Fig. 5
A10: CP-06 | B10: Ingreso | C10: Nombre y apellido sin conflicto (ej. Juan Pérez) | D10: Sugiere jperez | E10: No | F10: 46305 | G10: Ariel Correa | H10: Pasa | I10: Sugiere inicial nombre + apellido paterno. | J10: Fig. 6
A11: CP-07 | B11: Ingreso | C11: El correo jperez ya existe | D11: Sugiere jperezg (con inicial del apellido materno) | E11: Sí | F11: 46305 | G11: Ariel Correa | H11: Pasa | I11: Sugiere inicial nombre + apellido paterno + inicial apellido materno. | J11: Fig. 7
A12: CP-08 | B12: Ingreso | C12: Ninguna regla automática resuelve el conflicto | D12: Habilita edición manual del correo | E12: No | F12: 46310 | G12: Antonia Rocco | H12: Pasa (tras corrección) | I12: Si ya está ocupado el correo pide crearlo manualmente. | J12: Fig. 8
A13: CP-09 | B13: Ingreso | C13: Dos personas distintas con el mismo nombre | D13: El correo nunca se hereda entre ellas | E13: No | F13: 46305 | G13: Ariel Correa | H13: Pasa | I13: No hereda el correo a otra persona con el mismo nombre y distinto RUT y en caso de reingreso el sistema notifica de este. | J13: Fig. 9
A14: CP-10 | B14: Ingreso | C14: Envío correcto | D14: Solicitud en estado Pendiente, fecha de SLA calculada y notificación enviada | E14: No | F14: 46305 | G14: Ariel Correa | H14: Pasa | I14: Crea correctamente la solicitud. La notificación queda pendiente de definición (D-11). | J14: Fig. 10 | K14: D-11
A15: CP-11 | B15: Modificación | C15: Abrir modificación de un trabajador | D15: Muestra sus datos y accesos actuales | E15: No | F15: 46305 | G15: Ariel Correa | H15: Pasa | I15: Muestra los datos del trabajador seleccionado. | J15: Fig. 11
A16: CP-12 | B16: Modificación | C16: Enviar sin motivo de modificación | D16: Rechaza el envío | E16: No | F16: 46305 | G16: Ariel Correa | H16: Pasa | I16: No deja hacer modificación sin justificación. | J16: Fig. 12
A17: CP-13 | B17: Bloqueo | C17: Crear bloqueo | D17: Precarga los sistemas y carpetas vigentes del trabajador | E17: No | F17: 46305 | G17: Ariel Correa | H17: Pasa | I17: Precarga los sistemas y carpetas vigentes del trabajador. | J17: Fig. 13
A18: CP-14 | B18: Bloqueo | C18: Enviar sin motivo | D18: Rechaza el envío | E18: No | F18: 46305 | G18: Ariel Correa | H18: Pasa | I18: No deja enviar formulario sin justificación. | J18: Fig. 14
A19: CP-15 | B19: Bloqueo | C19: Crear bloqueo un sábado o domingo | D19: No permite crearlo | E19: Sí | F19: 46305 | G19: Ariel Correa | H19: Pasa | I19: No deja crear solicitudes los días sábado y domingo. | J19: Fig. 15
A20: CP-16 | B20: Bloqueo | C20: Crear bloqueo válido | D20: Estado Pendiente, SLA de mismo día hábil, RRHH recibe enlace | E20: No | H20: Pendiente | I20: Requiere un día hábil: queda por ejecutar en el próximo día hábil.
A21: CP-17 | B21: Bloqueo | C21: RRHH aprueba | D21: Pasa a En proceso y se notifica a TI | E21: No | F21: 46306 | G21: Ariel Correa | H21: Pasa (tras corrección) | I21: RRHH aprueba correctamente la solicitud. | J21: Fig. 16
A22: CP-18 | B22: Bloqueo | C22: RRHH rechaza sin motivo | D22: No permite rechazar | E22: No | F22: 46306 | G22: Ariel Correa | H22: Pasa (tras corrección) | I22: RRHH no puede rechazar solicitud sin justificación. | J22: Fig. 17
A23: CP-19 | B23: Bloqueo | C23: RRHH rechaza con motivo | D23: Estado Rechazada (final) | E23: No | F23: 46306 | G23: Ariel Correa | H23: Pasa (tras corrección) | I23: RRHH rechaza correctamente con justificación. | J23: Fig. 18
A24: CP-20 | B24: VPN | C24: Jefatura intenta abrir el formulario completo sin aprobación previa | D24: No lo ve ni puede acceder | E24: Sí | H24: Pendiente | I24: Módulo VPN no implementado
A25: CP-21 | B25: VPN | C25: Jefatura solicita acceso con motivo predefinido | D25: Estado Pendiente y TI es notificado | E25: No | H25: Pendiente | I25: Módulo VPN no implementado
A26: CP-22 | B26: VPN | C26: TI aprueba el acceso | D26: Se habilita el formulario solo para esa solicitud | E26: No | H26: Pendiente | I26: Módulo VPN no implementado
A27: CP-23 | B27: VPN | C27: TI rechaza el acceso | D27: Estado Rechazada y el flujo termina | E27: No | H27: Pendiente | I27: Módulo VPN no implementado
A28: CP-24 | B28: VPN | C28: Jefatura completa la ficha; TI la revisa y la envía | D28: En proceso al completarla; Completada al enviarse al proveedor | E28: No | H28: Pendiente | I28: Módulo VPN no implementado
A29: CP-25 | B29: Estados y cierre | C29: Marcar como completada una solicitud Pendiente | D29: No permitido; solo desde En proceso | E29: Sí | F29: 46306 | G29: Ariel Correa | H29: Pasa (tras corrección) | I29: En el sistema si hay una solicitud pendiente no permite realizar otra acción que no sea inciar o rechazar . | J29: Fig. 19, 20
A30: CP-26 | B30: Estados y cierre | C30: Marcar como completada una solicitud En proceso | D30: Registra usuario, fecha y hora; estado Completada | E30: No | F30: 46306 | G30: Ariel Correa | H30: Pasa (tras corrección) | I30: Registra de manera correcta usuario, fecha y hora; estado Completada. | J30: Fig. 21
A31: CP-27 | B31: Estados y cierre | C31: TI rechaza solicitud (Pendiente o En proceso) sin motivo | D31: No permite rechazar | E31: No | F31: 46306 | G31: Ariel Correa | H31: Pasa (tras corrección) | I31: No permite a AdminTI rechazar una solicitud sin justificación. | J31: Fig. 22
A32: CP-28 | B32: Estados y cierre | C32: Solicitud vencida por SLA | D32: Muestra alerta visual sin cambiar el estado | E32: No | F32: 46306 | G32: Ariel Correa | H32: Pasa (tras corrección) | I32: Muestra alerta visual sin cambiar el estado | J32: Fig. 23
A33: CP-29 | B33: Permisos y acceso | C33: Jefatura consulta trabajadores | D33: Solo ve los de su propia área | E33: No | F33: 46306 | G33: Ariel Correa | H33: Pasa (tras corrección) | I33: Rol Jefatura solo puede consultar trabajadores de su área. | J33: Fig. 24
A34: CP-30 | B34: Permisos y acceso | C34: Jefatura llama directo a la API por trabajadores de otra área | D34: Respuesta de acceso denegado | E34: Sí | F34: 46306 | G34: Ariel Correa | H34: Pasa (tras corrección) | I34: Rol Jefatura no tiene acceso a trabajadores de otra área llamando directo a la API. | J34: Fig. 25
A35: CP-31 | B35: Permisos y acceso | C35: RRHH intenta crear una solicitud de Ingreso | D35: No permitido | E35: Sí | F35: 46305 | G35: Ariel Correa | H35: Pasa | I35: RRHH no puede crear Ingresos (sin botón y la API responde 403). | J35: Fig. 26
A36: CP-32 | B36: Permisos y acceso | C36: Auditoría intenta crear, aprobar o rechazar | D36: No permitido (solo lectura) | E36: Sí | F36: 46305 | G36: Ariel Correa | H36: Pasa | I36: Auditoría solo puede consultar, no ve opción para crear y la API rechaza la creación. | J36: Fig. 27
A37: CP-33 | B37: Permisos y acceso | C37: Super Admin ejecuta acciones de cualquier rol | D37: Permitido y queda registrado | E37: No | F37: 46305 | G37: Ariel Correa | H37: Pasa | I37: Super Admin puede crear solicitudes y editar catálogos, la acción queda en el historial a su nombre. Se corrigió que el historial registrara siempre al mismo usuario (creadoPorId fijo en el frontend); ahora el backend identifica al usuario según el rol. Temporal hasta el login con AD (KB-02). | J37: Fig. 28, 29, 30
A38: CP-34 | B38: Permisos y acceso | C38: Iniciar sesión con credenciales de Active Directory | D38: Acceso según el rol asignado | E38: No | H38: Pendiente | I38: login con AD no implementado
A39: CP-35 | B39: Permisos y acceso | C39: Cerrar sesión y volver a una pantalla protegida | D39: Exige autenticación de nuevo | E39: No | H39: Pendiente | I39: login con AD no implementado
A40: CP-36 | B40: Catálogos, reportes e historial | C40: Admin agrega un sistema al catálogo | D40: Aparece de inmediato en los formularios | E40: No | F40: 46305 | G40: Ariel Correa | H40: Pasa | I40: El sistema agregado en Catálogos aparece de inmediato en el formulario de solicitud. | J40: Fig. 31
A41: CP-37 | B41: Catálogos, reportes e historial | C41: Rol sin permiso intenta editar catálogos | D41: No permitido | E41: No | F41: 46305 | G41: Ariel Correa | H41: Pasa | I41: Roles sin permiso no ven Catálogos y la API rechaza agregar, editar o desactivar. | J41: Fig. 32, 33
...

Sheet Resumen
A1: Resumen del seguimiento de pruebas
A3: Casos totales | B3: =COUNTA(Seguimiento!$A$5:$A$44)
A4: Ejecutados | B4: =B5+B6+B7
A5: Pasan a la primera ejecución | B5: =COUNTIF(Seguimiento!$H$5:$H$44,"Pasa")
A6: Pasan tras corrección | B6: =COUNTIF(Seguimiento!$H$5:$H$44,"Pasa (tras corrección)")
A7: Fallan | B7: =COUNTIF(Seguimiento!$H$5:$H$44,"Falla")
A8: Pendientes | B8: =COUNTIF(Seguimiento!$H$5:$H$44,"Pendiente")
A9: Avance de ejecución | B9: =B4/B3
A10: Casos críticos para automatizar | B10: =COUNTIF(Seguimiento!$E$5:$E$44,"Sí")
A12: Por módulo
A13: Módulo | B13: Total | C13: Pasan | D13: Pasan tras corrección | E13: Fallan | F13: Pendientes
A14: Ingreso | B14: =COUNTIF(Seguimiento!$B$5:$B$44,A14) | C14: =COUNTIFS(Seguimiento!$B$5:$B$44,$A14,Seguimiento!$H$5:$H$44,"Pasa") | D14: =COUNTIFS(Seguimiento!$B$5:$B$44,$A14,Seguimiento!$H$5:$H$44,"Pasa (tras corrección)") | E14: =COUNTIFS(Seguimiento!$B$5:$B$44,$A14,Seguimiento!$H$5:$H$44,"Falla") | F14: =COUNTIFS(Seguimiento!$B$5:$B$44,$A14,Seguimiento!$H$5:$H$44,"Pendiente")
A15: Modificación | B15: =COUNTIF(Seguimiento!$B$5:$B$44,A15) | C15: =COUNTIFS(Seguimiento!$B$5:$B$44,$A15,Seguimiento!$H$5:$H$44,"Pasa") | D15: =COUNTIFS(Seguimiento!$B$5:$B$44,$A15,Seguimiento!$H$5:$H$44,"Pasa (tras corrección)") | E15: =COUNTIFS(Seguimiento!$B$5:$B$44,$A15,Seguimiento!$H$5:$H$44,"Falla") | F15: =COUNTIFS(Seguimiento!$B$5:$B$44,$A15,Seguimiento!$H$5:$H$44,"Pendiente")
A16: Bloqueo | B16: =COUNTIF(Seguimiento!$B$5:$B$44,A16) | C16: =COUNTIFS(Seguimiento!$B$5:$B$44,$A16,Seguimiento!$H$5:$H$44,"Pasa") | D16: =COUNTIFS(Seguimiento!$B$5:$B$44,$A16,Seguimiento!$H$5:$H$44,"Pasa (tras corrección)") | E16: =COUNTIFS(Seguimiento!$B$5:$B$44,$A16,Seguimiento!$H$5:$H$44,"Falla") | F16: =COUNTIFS(Seguimiento!$B$5:$B$44,$A16,Seguimiento!$H$5:$H$44,"Pendiente")
A17: VPN | B17: =COUNTIF(Seguimiento!$B$5:$B$44,A17) | C17: =COUNTIFS(Seguimiento!$B$5:$B$44,$A17,Seguimiento!$H$5:$H$44,"Pasa") | D17: =COUNTIFS(Seguimiento!$B$5:$B$44,$A17,Seguimiento!$H$5:$H$44,"Pasa (tras corrección)") | E17: =COUNTIFS(Seguimiento!$B$5:$B$44,$A17,Seguimiento!$H$5:$H$44,"Falla") | F17: =COUNTIFS(Seguimiento!$B$5:$B$44,$A17,Seguimiento!$H$5:$H$44,"Pendiente")
A18: Estados y cierre | B18: =COUNTIF(Seguimiento!$B$5:$B$44,A18) | C18: =COUNTIFS(Seguimiento!$B$5:$B$44,$A18,Seguimiento!$H$5:$H$44,"Pasa") | D18: =COUNTIFS(Seguimiento!$B$5:$B$44,$A18,Seguimiento!$H$5:$H$44,"Pasa (tras corrección)") | E18: =COUNTIFS(Seguimiento!$B$5:$B$44,$A18,Seguimiento!$H$5:$H$44,"Falla") | F18: =COUNTIFS(Seguimiento!$B$5:$B$44,$A18,Seguimiento!$H$5:$H$44,"Pendiente")
A19: Permisos y acceso | B19: =COUNTIF(Seguimiento!$B$5:$B$44,A19) | C19: =COUNTIFS(Seguimiento!$B$5:$B$44,$A19,Seguimiento!$H$5:$H$44,"Pasa") | D19: =COUNTIFS(Seguimiento!$B$5:$B$44,$A19,Seguimiento!$H$5:$H$44,"Pasa (tras corrección)") | E19: =COUNTIFS(Seguimiento!$B$5:$B$44,$A19,Seguimiento!$H$5:$H$44,"Falla") | F19: =COUNTIFS(Seguimiento!$B$5:$B$44,$A19,Seguimiento!$H$5:$H$44,"Pendiente")
A20: Catálogos, reportes e historial | B20: =COUNTIF(Seguimiento!$B$5:$B$44,A20) | C20: =COUNTIFS(Seguimiento!$B$5:$B$44,$A20,Seguimiento!$H$5:$H$44,"Pasa") | D20: =COUNTIFS(Seguimiento!$B$5:$B$44,$A20,Seguimiento!$H$5:$H$44,"Pasa (tras corrección)") | E20: =COUNTIFS(Seguimiento!$B$5:$B$44,$A20,Seguimiento!$H$5:$H$44,"Falla") | F20: =COUNTIFS(Seguimiento!$B$5:$B$44,$A20,Seguimiento!$H$5:$H$44,"Pendiente")
A21: Total | B21: =SUM(B14:B20) | C21: =SUM(C14:C20) | D21: =SUM(D14:D20) | E21: =SUM(E14:E20) | F21: =SUM(F14:F20)

Sheet Defectos
A1: Defectos documentados
A2: Se listan los defectos referenciados en el Plan y Casos de Prueba y en los estados de avance. El registro completo de las 13 incidencias está en GitHub Issues.
A4: ID | B4: Descripción | C4: Casos relacionados | D4: Estado | E4: Dependencia
A5: D-01 | B5: Faltaba el campo Fecha de incorporación en el formulario de Ingreso | C5: CP-01 a CP-10 | D5: Cerrado
A6: D-04 | B6: El historial registraba siempre al mismo usuario (creadoPorId fijo en el frontend); ahora el backend identifica al usuario según el rol | C6: CP-33 | D6: Cerrado | E6: Temporal hasta el login con Active Directory (KB-02)
A7: D-05 | B7: Jefatura debía quedar limitada a los trabajadores de su propia área | C7: CP-29, CP-30 | D7: Cerrado
A8: D-06 | B8: Defecto abierto que depende del login real | C8: — | D8: Abierto | E8: Login con Active Directory (KB-02)
A9: D-07 | B9: Defecto abierto que depende de la carga de la dotación | C9: — | D9: Abierto | E9: Carga de la dotación
A10: D-11 | B10: Notificación a RRHH y SLA con días hábiles y feriados pendientes de definición con MAF | C10: CP-10 | D10: Abierto | E10: Definición con MAF
